2024-11-21 01:16:27 | INFO | information delivery successfully
2024-11-21 01:16:49 | INFO | information delivery successfully
2024-11-21 01:16:51 | INFO | information delivery successfully
2024-11-21 01:16:53 | INFO | information delivery successfully
2024-11-21 01:16:54 | INFO | information delivery successfully
2024-11-21 01:16:57 | INFO | information delivery successfully
2024-12-10 21:10:19 | ERROR | [CourseDao.get_all_courses]: (pymysql.err.OperationalError) (2003, "Can't connect to MySQL server on 'localhost' ([WinError 10061] No connection could be made because the target machine actively refused it)")
(Background on this error at: https://sqlalche.me/e/20/e3q8)
2024-12-10 21:10:19 | ERROR | Traceback (most recent call last):
  File "D:\MyNotes\CV\Study\venv\Lib\site-packages\pymysql\connections.py", line 649, in connect
    sock = socket.create_connection(
        (self.host, self.port), self.connect_timeout, **kwargs
    )
  File "C:\Users\molinaale\AppData\Local\Programs\Python\Python313\Lib\socket.py", line 864, in create_connection
    raise exceptions[0]
  File "C:\Users\molinaale\AppData\Local\Programs\Python\Python313\Lib\socket.py", line 849, in create_connection
    sock.connect(sa)
    ~~~~~~~~~~~~^^^^
ConnectionRefusedError: [WinError 10061] No connection could be made because the target machine actively refused it

During handling of the above exception, another exception occurred:

Traceback (most recent call last):
  File "D:\MyNotes\CV\Study\venv\Lib\site-packages\sqlalchemy\engine\base.py", line 146, in __init__
    self._dbapi_connection = engine.raw_connection()
                             ~~~~~~~~~~~~~~~~~~~~~^^
  File "D:\MyNotes\CV\Study\venv\Lib\site-packages\sqlalchemy\engine\base.py", line 3302, in raw_connection
    return self.pool.connect()
           ~~~~~~~~~~~~~~~~~^^
  File "D:\MyNotes\CV\Study\venv\Lib\site-packages\sqlalchemy\pool\base.py", line 449, in connect
    return _ConnectionFairy._checkout(self)
           ~~~~~~~~~~~~~~~~~~~~~~~~~~^^^^^^
  File "D:\MyNotes\CV\Study\venv\Lib\site-packages\sqlalchemy\pool\base.py", line 1263, in _checkout
    fairy = _ConnectionRecord.checkout(pool)
  File "D:\MyNotes\CV\Study\venv\Lib\site-packages\sqlalchemy\pool\base.py", line 712, in checkout
    rec = pool._do_get()
  File "D:\MyNotes\CV\Study\venv\Lib\site-packages\sqlalchemy\pool\impl.py", line 179, in _do_get
    with util.safe_reraise():
         ~~~~~~~~~~~~~~~~~^^
  File "D:\MyNotes\CV\Study\venv\Lib\site-packages\sqlalchemy\util\langhelpers.py", line 146, in __exit__
    raise exc_value.with_traceback(exc_tb)
  File "D:\MyNotes\CV\Study\venv\Lib\site-packages\sqlalchemy\pool\impl.py", line 177, in _do_get
    return self._create_connection()
           ~~~~~~~~~~~~~~~~~~~~~~~^^
  File "D:\MyNotes\CV\Study\venv\Lib\site-packages\sqlalchemy\pool\base.py", line 390, in _create_connection
    return _ConnectionRecord(self)
  File "D:\MyNotes\CV\Study\venv\Lib\site-packages\sqlalchemy\pool\base.py", line 674, in __init__
    self.__connect()
    ~~~~~~~~~~~~~~^^
  File "D:\MyNotes\CV\Study\venv\Lib\site-packages\sqlalchemy\pool\base.py", line 900, in __connect
    with util.safe_reraise():
         ~~~~~~~~~~~~~~~~~^^
  File "D:\MyNotes\CV\Study\venv\Lib\site-packages\sqlalchemy\util\langhelpers.py", line 146, in __exit__
    raise exc_value.with_traceback(exc_tb)
  File "D:\MyNotes\CV\Study\venv\Lib\site-packages\sqlalchemy\pool\base.py", line 896, in __connect
    self.dbapi_connection = connection = pool._invoke_creator(self)
                                         ~~~~~~~~~~~~~~~~~~~~^^^^^^
  File "D:\MyNotes\CV\Study\venv\Lib\site-packages\sqlalchemy\engine\create.py", line 643, in connect
    return dialect.connect(*cargs, **cparams)
           ~~~~~~~~~~~~~~~^^^^^^^^^^^^^^^^^^^
  File "D:\MyNotes\CV\Study\venv\Lib\site-packages\sqlalchemy\engine\default.py", line 621, in connect
    return self.loaded_dbapi.connect(*cargs, **cparams)
           ~~~~~~~~~~~~~~~~~~~~~~~~~^^^^^^^^^^^^^^^^^^^
  File "D:\MyNotes\CV\Study\venv\Lib\site-packages\pymysql\connections.py", line 361, in __init__
    self.connect()
    ~~~~~~~~~~~~^^
  File "D:\MyNotes\CV\Study\venv\Lib\site-packages\pymysql\connections.py", line 716, in connect
    raise exc
pymysql.err.OperationalError: (2003, "Can't connect to MySQL server on 'localhost' ([WinError 10061] No connection could be made because the target machine actively refused it)")

The above exception was the direct cause of the following exception:

Traceback (most recent call last):
  File "D:\MyNotes\CV\Study\src\database\CourseDao.py", line 33, in get_all_courses
    with engine.connect() as conn:
         ~~~~~~~~~~~~~~^^
  File "D:\MyNotes\CV\Study\venv\Lib\site-packages\sqlalchemy\engine\base.py", line 3278, in connect
    return self._connection_cls(self)
           ~~~~~~~~~~~~~~~~~~~~^^^^^^
  File "D:\MyNotes\CV\Study\venv\Lib\site-packages\sqlalchemy\engine\base.py", line 148, in __init__
    Connection._handle_dbapi_exception_noconnection(
    ~~~~~~~~~~~~~~~~~~~~~~~~~~~~~~~~~~~~~~~~~~~~~~~^
        err, dialect, engine
        ^^^^^^^^^^^^^^^^^^^^
    )
    ^
  File "D:\MyNotes\CV\Study\venv\Lib\site-packages\sqlalchemy\engine\base.py", line 2442, in _handle_dbapi_exception_noconnection
    raise sqlalchemy_exception.with_traceback(exc_info[2]) from e
  File "D:\MyNotes\CV\Study\venv\Lib\site-packages\sqlalchemy\engine\base.py", line 146, in __init__
    self._dbapi_connection = engine.raw_connection()
                             ~~~~~~~~~~~~~~~~~~~~~^^
  File "D:\MyNotes\CV\Study\venv\Lib\site-packages\sqlalchemy\engine\base.py", line 3302, in raw_connection
    return self.pool.connect()
           ~~~~~~~~~~~~~~~~~^^
  File "D:\MyNotes\CV\Study\venv\Lib\site-packages\sqlalchemy\pool\base.py", line 449, in connect
    return _ConnectionFairy._checkout(self)
           ~~~~~~~~~~~~~~~~~~~~~~~~~~^^^^^^
  File "D:\MyNotes\CV\Study\venv\Lib\site-packages\sqlalchemy\pool\base.py", line 1263, in _checkout
    fairy = _ConnectionRecord.checkout(pool)
  File "D:\MyNotes\CV\Study\venv\Lib\site-packages\sqlalchemy\pool\base.py", line 712, in checkout
    rec = pool._do_get()
  File "D:\MyNotes\CV\Study\venv\Lib\site-packages\sqlalchemy\pool\impl.py", line 179, in _do_get
    with util.safe_reraise():
         ~~~~~~~~~~~~~~~~~^^
  File "D:\MyNotes\CV\Study\venv\Lib\site-packages\sqlalchemy\util\langhelpers.py", line 146, in __exit__
    raise exc_value.with_traceback(exc_tb)
  File "D:\MyNotes\CV\Study\venv\Lib\site-packages\sqlalchemy\pool\impl.py", line 177, in _do_get
    return self._create_connection()
           ~~~~~~~~~~~~~~~~~~~~~~~^^
  File "D:\MyNotes\CV\Study\venv\Lib\site-packages\sqlalchemy\pool\base.py", line 390, in _create_connection
    return _ConnectionRecord(self)
  File "D:\MyNotes\CV\Study\venv\Lib\site-packages\sqlalchemy\pool\base.py", line 674, in __init__
    self.__connect()
    ~~~~~~~~~~~~~~^^
  File "D:\MyNotes\CV\Study\venv\Lib\site-packages\sqlalchemy\pool\base.py", line 900, in __connect
    with util.safe_reraise():
         ~~~~~~~~~~~~~~~~~^^
  File "D:\MyNotes\CV\Study\venv\Lib\site-packages\sqlalchemy\util\langhelpers.py", line 146, in __exit__
    raise exc_value.with_traceback(exc_tb)
  File "D:\MyNotes\CV\Study\venv\Lib\site-packages\sqlalchemy\pool\base.py", line 896, in __connect
    self.dbapi_connection = connection = pool._invoke_creator(self)
                                         ~~~~~~~~~~~~~~~~~~~~^^^^^^
  File "D:\MyNotes\CV\Study\venv\Lib\site-packages\sqlalchemy\engine\create.py", line 643, in connect
    return dialect.connect(*cargs, **cparams)
           ~~~~~~~~~~~~~~~^^^^^^^^^^^^^^^^^^^
  File "D:\MyNotes\CV\Study\venv\Lib\site-packages\sqlalchemy\engine\default.py", line 621, in connect
    return self.loaded_dbapi.connect(*cargs, **cparams)
           ~~~~~~~~~~~~~~~~~~~~~~~~~^^^^^^^^^^^^^^^^^^^
  File "D:\MyNotes\CV\Study\venv\Lib\site-packages\pymysql\connections.py", line 361, in __init__
    self.connect()
    ~~~~~~~~~~~~^^
  File "D:\MyNotes\CV\Study\venv\Lib\site-packages\pymysql\connections.py", line 716, in connect
    raise exc
sqlalchemy.exc.OperationalError: (pymysql.err.OperationalError) (2003, "Can't connect to MySQL server on 'localhost' ([WinError 10061] No connection could be made because the target machine actively refused it)")
(Background on this error at: https://sqlalche.me/e/20/e3q8)

2024-12-10 21:15:31 | INFO | information delivery successfully
